<?xml version="1.0"?>
<robot xmlns:xacro="http://ros.org/wiki/xacro">
  <!-- Base Link -->
  <link name="base_link">
    <visual>
      <geometry>
        <box size="0.75 0.4 0.1"/>
      </geometry>
      <material name="gray"/>
    </visual>
    
    <xacro:box_inertial mass="1" x="0.75" y="0.4" z="0.1"/>
    
    <collision>
      <geometry>
        <box size="0.75 0.4 0.1"/>
      </geometry>
    </collision>
  </link>

  <!-- Right Wheel -->
  <link name="wheel_right_link">
    <xacro:cylinder_inertial mass="2" radius="0.15" length="0.1"/>
    
    <visual>
      <geometry>
        <cylinder radius="0.15" length="0.1"/>
      </geometry>
      <material name="white"/>
    </visual>
    
    <collision>
      <geometry>
        <cylinder radius="0.15" length="0.1"/>
      </geometry>
      <surface>
        <friction>
          <ode>
            <mu>0</mu>
            <mu2>0</mu2>
            <slip1>1.0</slip1>
            <slip2>1.0</slip2>
          </ode>
        </friction>
      </surface>
      <contact_coefficients mu="1" kp="1e+13" kd="1.0"/>
    </collision>
  </link>

  <joint name="wheel_right_joint" type="continuous">
    <origin xyz="0.2 0.25 0.0" rpy="1.57 0.0 0.0"/>
    <parent link="base_link"/>
    <child link="wheel_right_link"/>
    <axis xyz="0.0 0.0 1.0"/>
  </joint>

  <!-- Left Wheel -->
  <link name="wheel_left_link">
    <xacro:cylinder_inertial mass="2" radius="0.15" length="0.1"/>
    
    <visual>
      <geometry>
        <cylinder radius="0.15" length="0.1"/>
      </geometry>
      <material name="white"/>
    </visual>
    
    <collision>
      <geometry>
        <cylinder radius="0.15" length="0.1"/>
      </geometry>
      <surface>
        <friction>
          <ode>
            <mu>0</mu>
            <mu2>0</mu2>
            <slip1>1.0</slip1>
            <slip2>1.0</slip2>
          </ode>
        </friction>
      </surface>
      <contact_coefficients mu="1" kp="1e+13" kd="1.0"/>
    </collision>
  </link>

  <joint name="wheel_left_joint" type="continuous">
    <origin xyz="0.2 -0.25 0.0" rpy="1.57 0.0 0.0"/>
    <parent link="base_link"/>
    <child link="wheel_left_link"/>
    <axis xyz="0.0 0.0 1.0"/>
  </joint>

  <!-- Caster Wheel -->
  <link name="caster">
    <xacro:sphere_inertial mass="1" radius="0.08"/>
    
    <visual>
      <geometry>
        <sphere radius=".08" />
      </geometry>
      <material name="white" />
    </visual>
    
    <collision>
      <geometry>
        <sphere radius=".08" />
      </geometry>
      <surface>
        <friction>
          <ode>
            <mu>0</mu>
            <mu2>0</mu2>
            <slip1>1.0</slip1>
            <slip2>1.0</slip2>
          </ode>
        </friction>
      </surface>
    </collision>
  </link>

  <joint name="caster_joint" type="continuous">
    <origin xyz="-0.3 0.0 -0.07" rpy="0.0 0.0 0.0"/>
    <axis xyz="0 0 1" />
    <parent link="base_link"/>
    <child link="caster"/>
  </joint>

  <!-- Laser Link -->
  <link name="laser">
    <xacro:cylinder_inertial mass="1" radius="0.05" length="0.05"/>
    
    <visual>
      <geometry>
        <cylinder radius="0.05" length="0.05"/> 
      </geometry>
    </visual>
    
    <collision>
      <origin/>
      <geometry>
        <sphere radius=".08" />
      </geometry>
    </collision>
  </link>
  
  <joint name="laser_joint" type="fixed">
    <origin xyz="-0.32 0.0 0.08" rpy="0.0 0.0 3.14"/>
    <axis xyz="0 0 1" />
    <parent link="base_link"/>
    <child link="laser"/>
  </joint>
</robot>